🍪 Cookies aceitos.

🔍 Buscando empresa: RRRP3
❌ Empresa não encontrada: RRRP3

🔍 Buscando empresa: TTEN3
✅ Empresa encontrada: TTEN3 → TTEN
📄 Relatórios Estruturados selecionado.
📅 Ano selecionado: 2010
❌ Nenhum Formulário de Referência disponível para 2010
📅 Ano selecionado: 2011
❌ Nenhum Formulário de Referência disponível para 2011
📅 Ano selecionado: 2012
❌ Nenhum Formulário de Referência disponível para 2012
📅 Ano selecionado: 2013
❌ Nenhum Formulário de Referência disponível para 2013
📅 Ano selecionado: 2014
❌ Nenhum Formulário de Referência disponível para 2014
📅 Ano selecionado: 2015
❌ Nenhum Formulário de Referência disponível para 2015
📅 Ano selecionado: 2016
❌ Nenhum Formulário de Referência disponível para 2016
📅 Ano selecionado: 2017
❌ Nenhum Formulário de Referência disponível para 2017
📅 Ano selecionado: 2018
❌ Nenhum Formulário de Referência disponível para 2018
📅 Ano selecionado: 2019
❌ Nenhum Formulário de Referência disponível para 2019
📅 Ano selecionado: 2020
❌ Nenhum Formulário de Referência disponível para 2020
📅 Ano selecionado: 2021
📝 Formulário de Referência encontrado para 2021: https://www.rad.cvm.gov.br/ENET/frmNBC.aspx?NSD=113054
📄 Botão 'Salvar em PDF' localizado com sucesso.
🧭 Entrou no iframe do modal com sucesso.
☑️ Checkbox 'Todos' desmarcado dentro do modal.
↩️ Retornado com sucesso ao iframe.
📅 Ano selecionado: 2022
📝 Formulário de Referência encontrado para 2022: https://www.rad.cvm.gov.br/ENET/frmNBC.aspx?NSD=127053
📄 Botão 'Salvar em PDF' localizado com sucesso.
🧭 Entrou no iframe do modal com sucesso.
☑️ Checkbox 'Todos' desmarcado dentro do modal.
↩️ Retornado com sucesso ao iframe.
📅 Ano selecionado: 2023
📝 Formulário de Referência encontrado para 2023: https://www.rad.cvm.gov.br/ENET/frmNBC.aspx?NSD=133703
📄 Botão 'Salvar em PDF' localizado com sucesso.
🧭 Entrou no iframe do modal com sucesso.
☑️ Checkbox 'Todos' desmarcado dentro do modal.
↩️ Retornado com sucesso ao iframe.
📅 Ano selecionado: 2024
📝 Formulário de Referência encontrado para 2024: https://www.rad.cvm.gov.br/ENET/frmNBC.aspx?NSD=147072
📄 Botão 'Salvar em PDF' localizado com sucesso.
🧭 Entrou no iframe do modal com sucesso.
☑️ Checkbox 'Todos' desmarcado dentro do modal.
↩️ Retornado com sucesso ao iframe.

🔍 Buscando empresa: QVQP3B
❌ Erro ao processar QVQP3B: Message: 
Stacktrace:
#0 0x57165f6e629a <unknown>
#1 0x57165f152040 <unknown>
#2 0x57165f1a3990 <unknown>
#3 0x57165f1a3b81 <unknown>
#4 0x57165f1f2664 <unknown>
#5 0x57165f1c96bd <unknown>
#6 0x57165f1eface <unknown>
#7 0x57165f1c9463 <unknown>
#8 0x57165f195c55 <unknown>
#9 0x57165f1968c1 <unknown>
#10 0x57165f6ab1bb <unknown>
#11 0x57165f6af0c9 <unknown>
#12 0x57165f693a39 <unknown>
#13 0x57165f6afc78 <unknown>
#14 0x57165f6786bf <unknown>
#15 0x57165f6d3948 <unknown>
#16 0x57165f6d3b26 <unknown>
#17 0x57165f6e5176 <unknown>
#18 0x79053509caa4 <unknown>
#19 0x790535129c3c <unknown>

✅ Nenhum banner de cookies detectado.

🔍 Buscando empresa: EALT3
✅ Empresa encontrada: EALT3 → EALT
📄 Relatórios Estruturados selecionado.
📅 Ano selecionado: 2010
❌ Nenhum Formulário de Referência disponível para 2010
📅 Ano selecionado: 2011
❌ Nenhum Formulário de Referência disponível para 2011
📅 Ano selecionado: 2012
📝 Formulário de Referência encontrado para 2012: https://www.rad.cvm.gov.br/ENET/frmNBC.aspx?NSD=24993
📄 Botão 'Salvar em PDF' localizado com sucesso.
🧭 Entrou no iframe do modal com sucesso.
☑️ Checkbox 'Todos' desmarcado dentro do modal.
↩️ Retornado com sucesso ao iframe.
📅 Ano selecionado: 2013
📝 Formulário de Referência encontrado para 2013: https://www.rad.cvm.gov.br/ENET/frmNBC.aspx?NSD=32148
📄 Botão 'Salvar em PDF' localizado com sucesso.
❌ Botão 'Salvar em PDF' não encontrado.
❌ Nenhum Formulário de Referência disponível para 2013
⚠️ Não foi possível selecionar o ano 2014: HTTPConnectionPool(host='localhost', port=45483): Max retries exceeded with url: /session/baafe3183db8687cb0a4edb742184ac9/element/f.048EB2085D26BE57E5A973E52EF3040C.d.9CA58E1B6C602EB5FE648F529F363121.e.327/elements (Caused by NewConnectionError('<urllib3.connection.HTTPConnection object at 0x73a981d4f5c0>: Failed to establish a new connection: [Errno 111] Connection refused'))
⚠️ Não foi possível selecionar o ano 2015: HTTPConnectionPool(host='localhost', port=45483): Max retries exceeded with url: /session/baafe3183db8687cb0a4edb742184ac9/element/f.048EB2085D26BE57E5A973E52EF3040C.d.9CA58E1B6C602EB5FE648F529F363121.e.327/elements (Caused by NewConnectionError('<urllib3.connection.HTTPConnection object at 0x73a981da8290>: Failed to establish a new connection: [Errno 111] Connection refused'))
⚠️ Não foi possível selecionar o ano 2016: HTTPConnectionPool(host='localhost', port=45483): Max retries exceeded with url: /session/baafe3183db8687cb0a4edb742184ac9/element/f.048EB2085D26BE57E5A973E52EF3040C.d.9CA58E1B6C602EB5FE648F529F363121.e.327/elements (Caused by NewConnectionError('<urllib3.connection.HTTPConnection object at 0x73a981da8aa0>: Failed to establish a new connection: [Errno 111] Connection refused'))
⚠️ Não foi possível selecionar o ano 2017: HTTPConnectionPool(host='localhost', port=45483): Max retries exceeded with url: /session/baafe3183db8687cb0a4edb742184ac9/element/f.048EB2085D26BE57E5A973E52EF3040C.d.9CA58E1B6C602EB5FE648F529F363121.e.327/elements (Caused by NewConnectionError('<urllib3.connection.HTTPConnection object at 0x73a981d4f320>: Failed to establish a new connection: [Errno 111] Connection refused'))
⚠️ Não foi possível selecionar o ano 2018: HTTPConnectionPool(host='localhost', port=45483): Max retries exceeded with url: /session/baafe3183db8687cb0a4edb742184ac9/element/f.048EB2085D26BE57E5A973E52EF3040C.d.9CA58E1B6C602EB5FE648F529F363121.e.327/elements (Caused by NewConnectionError('<urllib3.connection.HTTPConnection object at 0x73a981d4fb00>: Failed to establish a new connection: [Errno 111] Connection refused'))
⚠️ Não foi possível selecionar o ano 2019: HTTPConnectionPool(host='localhost', port=45483): Max retries exceeded with url: /session/baafe3183db8687cb0a4edb742184ac9/element/f.048EB2085D26BE57E5A973E52EF3040C.d.9CA58E1B6C602EB5FE648F529F363121.e.327/elements (Caused by NewConnectionError('<urllib3.connection.HTTPConnection object at 0x73a981da8800>: Failed to establish a new connection: [Errno 111] Connection refused'))
⚠️ Não foi possível selecionar o ano 2020: HTTPConnectionPool(host='localhost', port=45483): Max retries exceeded with url: /session/baafe3183db8687cb0a4edb742184ac9/element/f.048EB2085D26BE57E5A973E52EF3040C.d.9CA58E1B6C602EB5FE648F529F363121.e.327/elements (Caused by NewConnectionError('<urllib3.connection.HTTPConnection object at 0x73a981da9160>: Failed to establish a new connection: [Errno 111] Connection refused'))
⚠️ Não foi possível selecionar o ano 2021: HTTPConnectionPool(host='localhost', port=45483): Max retries exceeded with url: /session/baafe3183db8687cb0a4edb742184ac9/element/f.048EB2085D26BE57E5A973E52EF3040C.d.9CA58E1B6C602EB5FE648F529F363121.e.327/elements (Caused by NewConnectionError('<urllib3.connection.HTTPConnection object at 0x73a981d4f200>: Failed to establish a new connection: [Errno 111] Connection refused'))
⚠️ Não foi possível selecionar o ano 2022: HTTPConnectionPool(host='localhost', port=45483): Max retries exceeded with url: /session/baafe3183db8687cb0a4edb742184ac9/element/f.048EB2085D26BE57E5A973E52EF3040C.d.9CA58E1B6C602EB5FE648F529F363121.e.327/elements (Caused by NewConnectionError('<urllib3.connection.HTTPConnection object at 0x73a981d4f1a0>: Failed to establish a new connection: [Errno 111] Connection refused'))
⚠️ Não foi possível selecionar o ano 2023: HTTPConnectionPool(host='localhost', port=45483): Max retries exceeded with url: /session/baafe3183db8687cb0a4edb742184ac9/element/f.048EB2085D26BE57E5A973E52EF3040C.d.9CA58E1B6C602EB5FE648F529F363121.e.327/elements (Caused by NewConnectionError('<urllib3.connection.HTTPConnection object at 0x73a981da81a0>: Failed to establish a new connection: [Errno 111] Connection refused'))
⚠️ Não foi possível selecionar o ano 2024: HTTPConnectionPool(host='localhost', port=45483): Max retries exceeded with url: /session/baafe3183db8687cb0a4edb742184ac9/element/f.048EB2085D26BE57E5A973E52EF3040C.d.9CA58E1B6C602EB5FE648F529F363121.e.327/elements (Caused by NewConnectionError('<urllib3.connection.HTTPConnection object at 0x73a981da8ef0>: Failed to establish a new connection: [Errno 111] Connection refused'))

🔍 Buscando empresa: EALT4
❌ Erro ao processar EALT4: HTTPConnectionPool(host='localhost', port=45483): Max retries exceeded with url: /session/baafe3183db8687cb0a4edb742184ac9/element (Caused by NewConnectionError('<urllib3.connection.HTTPConnection object at 0x73a981d4f830>: Failed to establish a new connection: [Errno 111] Connection refused'))
Traceback (most recent call last):
  File "/home/darkcover1/.cache/pypoetry/virtualenvs/work-text-a7ILbfPj-py3.12/lib/python3.12/site-packages/urllib3/connection.py", line 198, in _new_conn
    sock = connection.create_connection(
           ^^^^^^^^^^^^^^^^^^^^^^^^^^^^^
  File "/home/darkcover1/.cache/pypoetry/virtualenvs/work-text-a7ILbfPj-py3.12/lib/python3.12/site-packages/urllib3/util/connection.py", line 85, in create_connection
    raise err
  File "/home/darkcover1/.cache/pypoetry/virtualenvs/work-text-a7ILbfPj-py3.12/lib/python3.12/site-packages/urllib3/util/connection.py", line 73, in create_connection
    sock.connect(sa)
ConnectionRefusedError: [Errno 111] Connection refused

The above exception was the direct cause of the following exception:

Traceback (most recent call last):
  File "/home/darkcover1/.cache/pypoetry/virtualenvs/work-text-a7ILbfPj-py3.12/lib/python3.12/site-packages/urllib3/connectionpool.py", line 787, in urlopen
    response = self._make_request(
               ^^^^^^^^^^^^^^^^^^^
  File "/home/darkcover1/.cache/pypoetry/virtualenvs/work-text-a7ILbfPj-py3.12/lib/python3.12/site-packages/urllib3/connectionpool.py", line 493, in _make_request
    conn.request(
  File "/home/darkcover1/.cache/pypoetry/virtualenvs/work-text-a7ILbfPj-py3.12/lib/python3.12/site-packages/urllib3/connection.py", line 445, in request
    self.endheaders()
  File "/usr/lib/python3.12/http/client.py", line 1331, in endheaders
    self._send_output(message_body, encode_chunked=encode_chunked)
  File "/usr/lib/python3.12/http/client.py", line 1091, in _send_output
    self.send(msg)
  File "/usr/lib/python3.12/http/client.py", line 1035, in send
    self.connect()
  File "/home/darkcover1/.cache/pypoetry/virtualenvs/work-text-a7ILbfPj-py3.12/lib/python3.12/site-packages/urllib3/connection.py", line 276, in connect
    self.sock = self._new_conn()
                ^^^^^^^^^^^^^^^^
  File "/home/darkcover1/.cache/pypoetry/virtualenvs/work-text-a7ILbfPj-py3.12/lib/python3.12/site-packages/urllib3/connection.py", line 213, in _new_conn
    raise NewConnectionError(
urllib3.exceptions.NewConnectionError: <urllib3.connection.HTTPConnection object at 0x73a981d4f830>: Failed to establish a new connection: [Errno 111] Connection refused

The above exception was the direct cause of the following exception:

Traceback (most recent call last):
  File "/home/darkcover1/Documentos/Work_Text/B3/Códigos/Extractor/version2.py", line 46, in <module>
    campo = wait.until(EC.element_to_be_clickable((By.ID, "keyword")))
            ^^^^^^^^^^^^^^^^^^^^^^^^^^^^^^^^^^^^^^^^^^^^^^^^^^^^^^^^^^
  File "/home/darkcover1/.cache/pypoetry/virtualenvs/work-text-a7ILbfPj-py3.12/lib/python3.12/site-packages/selenium/webdriver/support/wait.py", line 129, in until
    value = method(self._driver)
            ^^^^^^^^^^^^^^^^^^^^
  File "/home/darkcover1/.cache/pypoetry/virtualenvs/work-text-a7ILbfPj-py3.12/lib/python3.12/site-packages/selenium/webdriver/support/expected_conditions.py", line 622, in _predicate
    target = driver.find_element(*target)  # grab element at locator
             ^^^^^^^^^^^^^^^^^^^^^^^^^^^^
  File "/home/darkcover1/.cache/pypoetry/virtualenvs/work-text-a7ILbfPj-py3.12/lib/python3.12/site-packages/selenium/webdriver/remote/webdriver.py", line 914, in find_element
    return self.execute(Command.FIND_ELEMENT, {"using": by, "value": value})["value"]
           ^^^^^^^^^^^^^^^^^^^^^^^^^^^^^^^^^^^^^^^^^^^^^^^^^^^^^^^^^^^^^^^^^
  File "/home/darkcover1/.cache/pypoetry/virtualenvs/work-text-a7ILbfPj-py3.12/lib/python3.12/site-packages/selenium/webdriver/remote/webdriver.py", line 445, in execute
    response = self.command_executor.execute(driver_command, params)
               ^^^^^^^^^^^^^^^^^^^^^^^^^^^^^^^^^^^^^^^^^^^^^^^^^^^^^
  File "/home/darkcover1/.cache/pypoetry/virtualenvs/work-text-a7ILbfPj-py3.12/lib/python3.12/site-packages/selenium/webdriver/remote/remote_connection.py", line 404, in execute
    return self._request(command_info[0], url, body=data)
           ^^^^^^^^^^^^^^^^^^^^^^^^^^^^^^^^^^^^^^^^^^^^^^
  File "/home/darkcover1/.cache/pypoetry/virtualenvs/work-text-a7ILbfPj-py3.12/lib/python3.12/site-packages/selenium/webdriver/remote/remote_connection.py", line 428, in _request
    response = self._conn.request(method, url, body=body, headers=headers, timeout=self._client_config.timeout)
               ^^^^^^^^^^^^^^^^^^^^^^^^^^^^^^^^^^^^^^^^^^^^^^^^^^^^^^^^^^^^^^^^^^^^^^^^^^^^^^^^^^^^^^^^^^^^^^^^
  File "/home/darkcover1/.cache/pypoetry/virtualenvs/work-text-a7ILbfPj-py3.12/lib/python3.12/site-packages/urllib3/_request_methods.py", line 143, in request
    return self.request_encode_body(
           ^^^^^^^^^^^^^^^^^^^^^^^^^
  File "/home/darkcover1/.cache/pypoetry/virtualenvs/work-text-a7ILbfPj-py3.12/lib/python3.12/site-packages/urllib3/_request_methods.py", line 278, in request_encode_body
    return self.urlopen(method, url, **extra_kw)
           ^^^^^^^^^^^^^^^^^^^^^^^^^^^^^^^^^^^^^
  File "/home/darkcover1/.cache/pypoetry/virtualenvs/work-text-a7ILbfPj-py3.12/lib/python3.12/site-packages/urllib3/poolmanager.py", line 443, in urlopen
    response = conn.urlopen(method, u.request_uri, **kw)
               ^^^^^^^^^^^^^^^^^^^^^^^^^^^^^^^^^^^^^^^^^
  File "/home/darkcover1/.cache/pypoetry/virtualenvs/work-text-a7ILbfPj-py3.12/lib/python3.12/site-packages/urllib3/connectionpool.py", line 871, in urlopen
    return self.urlopen(
           ^^^^^^^^^^^^^
  File "/home/darkcover1/.cache/pypoetry/virtualenvs/work-text-a7ILbfPj-py3.12/lib/python3.12/site-packages/urllib3/connectionpool.py", line 871, in urlopen
    return self.urlopen(
           ^^^^^^^^^^^^^
  File "/home/darkcover1/.cache/pypoetry/virtualenvs/work-text-a7ILbfPj-py3.12/lib/python3.12/site-packages/urllib3/connectionpool.py", line 871, in urlopen
    return self.urlopen(
           ^^^^^^^^^^^^^
  File "/home/darkcover1/.cache/pypoetry/virtualenvs/work-text-a7ILbfPj-py3.12/lib/python3.12/site-packages/urllib3/connectionpool.py", line 841, in urlopen
    retries = retries.increment(
              ^^^^^^^^^^^^^^^^^^
  File "/home/darkcover1/.cache/pypoetry/virtualenvs/work-text-a7ILbfPj-py3.12/lib/python3.12/site-packages/urllib3/util/retry.py", line 519, in increment
    raise MaxRetryError(_pool, url, reason) from reason  # type: ignore[arg-type]
    ^^^^^^^^^^^^^^^^^^^^^^^^^^^^^^^^^^^^^^^^^^^^^^^^^^^
urllib3.exceptions.MaxRetryError: HTTPConnectionPool(host='localhost', port=45483): Max retries exceeded with url: /session/baafe3183db8687cb0a4edb742184ac9/element (Caused by NewConnectionError('<urllib3.connection.HTTPConnection object at 0x73a981d4f830>: Failed to establish a new connection: [Errno 111] Connection refused'))

During handling of the above exception, another exception occurred:

Traceback (most recent call last):
  File "/home/darkcover1/.cache/pypoetry/virtualenvs/work-text-a7ILbfPj-py3.12/lib/python3.12/site-packages/urllib3/connection.py", line 198, in _new_conn
    sock = connection.create_connection(
           ^^^^^^^^^^^^^^^^^^^^^^^^^^^^^
  File "/home/darkcover1/.cache/pypoetry/virtualenvs/work-text-a7ILbfPj-py3.12/lib/python3.12/site-packages/urllib3/util/connection.py", line 85, in create_connection
    raise err
  File "/home/darkcover1/.cache/pypoetry/virtualenvs/work-text-a7ILbfPj-py3.12/lib/python3.12/site-packages/urllib3/util/connection.py", line 73, in create_connection
    sock.connect(sa)
ConnectionRefusedError: [Errno 111] Connection refused

The above exception was the direct cause of the following exception:

Traceback (most recent call last):
  File "/home/darkcover1/.cache/pypoetry/virtualenvs/work-text-a7ILbfPj-py3.12/lib/python3.12/site-packages/urllib3/connectionpool.py", line 787, in urlopen
    response = self._make_request(
               ^^^^^^^^^^^^^^^^^^^
  File "/home/darkcover1/.cache/pypoetry/virtualenvs/work-text-a7ILbfPj-py3.12/lib/python3.12/site-packages/urllib3/connectionpool.py", line 493, in _make_request
    conn.request(
  File "/home/darkcover1/.cache/pypoetry/virtualenvs/work-text-a7ILbfPj-py3.12/lib/python3.12/site-packages/urllib3/connection.py", line 445, in request
    self.endheaders()
  File "/usr/lib/python3.12/http/client.py", line 1331, in endheaders
    self._send_output(message_body, encode_chunked=encode_chunked)
  File "/usr/lib/python3.12/http/client.py", line 1091, in _send_output
    self.send(msg)
  File "/usr/lib/python3.12/http/client.py", line 1035, in send
    self.connect()
  File "/home/darkcover1/.cache/pypoetry/virtualenvs/work-text-a7ILbfPj-py3.12/lib/python3.12/site-packages/urllib3/connection.py", line 276, in connect
    self.sock = self._new_conn()
                ^^^^^^^^^^^^^^^^
  File "/home/darkcover1/.cache/pypoetry/virtualenvs/work-text-a7ILbfPj-py3.12/lib/python3.12/site-packages/urllib3/connection.py", line 213, in _new_conn
    raise NewConnectionError(
urllib3.exceptions.NewConnectionError: <urllib3.connection.HTTPConnection object at 0x73a981d4f350>: Failed to establish a new connection: [Errno 111] Connection refused

The above exception was the direct cause of the following exception:

Traceback (most recent call last):
  File "/home/darkcover1/Documentos/Work_Text/B3/Códigos/Extractor/version2.py", line 187, in <module>
    driver.switch_to.default_content()
  File "/home/darkcover1/.cache/pypoetry/virtualenvs/work-text-a7ILbfPj-py3.12/lib/python3.12/site-packages/selenium/webdriver/remote/switch_to.py", line 66, in default_content
    self._driver.execute(Command.SWITCH_TO_FRAME, {"id": None})
  File "/home/darkcover1/.cache/pypoetry/virtualenvs/work-text-a7ILbfPj-py3.12/lib/python3.12/site-packages/selenium/webdriver/remote/webdriver.py", line 445, in execute
    response = self.command_executor.execute(driver_command, params)
               ^^^^^^^^^^^^^^^^^^^^^^^^^^^^^^^^^^^^^^^^^^^^^^^^^^^^^
  File "/home/darkcover1/.cache/pypoetry/virtualenvs/work-text-a7ILbfPj-py3.12/lib/python3.12/site-packages/selenium/webdriver/remote/remote_connection.py", line 404, in execute
    return self._request(command_info[0], url, body=data)
           ^^^^^^^^^^^^^^^^^^^^^^^^^^^^^^^^^^^^^^^^^^^^^^
  File "/home/darkcover1/.cache/pypoetry/virtualenvs/work-text-a7ILbfPj-py3.12/lib/python3.12/site-packages/selenium/webdriver/remote/remote_connection.py", line 428, in _request
    response = self._conn.request(method, url, body=body, headers=headers, timeout=self._client_config.timeout)
               ^^^^^^^^^^^^^^^^^^^^^^^^^^^^^^^^^^^^^^^^^^^^^^^^^^^^^^^^^^^^^^^^^^^^^^^^^^^^^^^^^^^^^^^^^^^^^^^^
  File "/home/darkcover1/.cache/pypoetry/virtualenvs/work-text-a7ILbfPj-py3.12/lib/python3.12/site-packages/urllib3/_request_methods.py", line 143, in request
    return self.request_encode_body(
           ^^^^^^^^^^^^^^^^^^^^^^^^^
  File "/home/darkcover1/.cache/pypoetry/virtualenvs/work-text-a7ILbfPj-py3.12/lib/python3.12/site-packages/urllib3/_request_methods.py", line 278, in request_encode_body
    return self.urlopen(method, url, **extra_kw)
           ^^^^^^^^^^^^^^^^^^^^^^^^^^^^^^^^^^^^^
  File "/home/darkcover1/.cache/pypoetry/virtualenvs/work-text-a7ILbfPj-py3.12/lib/python3.12/site-packages/urllib3/poolmanager.py", line 443, in urlopen
    response = conn.urlopen(method, u.request_uri, **kw)
               ^^^^^^^^^^^^^^^^^^^^^^^^^^^^^^^^^^^^^^^^^
  File "/home/darkcover1/.cache/pypoetry/virtualenvs/work-text-a7ILbfPj-py3.12/lib/python3.12/site-packages/urllib3/connectionpool.py", line 871, in urlopen
    return self.urlopen(
           ^^^^^^^^^^^^^
  File "/home/darkcover1/.cache/pypoetry/virtualenvs/work-text-a7ILbfPj-py3.12/lib/python3.12/site-packages/urllib3/connectionpool.py", line 871, in urlopen
    return self.urlopen(
           ^^^^^^^^^^^^^
  File "/home/darkcover1/.cache/pypoetry/virtualenvs/work-text-a7ILbfPj-py3.12/lib/python3.12/site-packages/urllib3/connectionpool.py", line 871, in urlopen
    return self.urlopen(
           ^^^^^^^^^^^^^
  File "/home/darkcover1/.cache/pypoetry/virtualenvs/work-text-a7ILbfPj-py3.12/lib/python3.12/site-packages/urllib3/connectionpool.py", line 841, in urlopen
    retries = retries.increment(
              ^^^^^^^^^^^^^^^^^^
  File "/home/darkcover1/.cache/pypoetry/virtualenvs/work-text-a7ILbfPj-py3.12/lib/python3.12/site-packages/urllib3/util/retry.py", line 519, in increment
    raise MaxRetryError(_pool, url, reason) from reason  # type: ignore[arg-type]
    ^^^^^^^^^^^^^^^^^^^^^^^^^^^^^^^^^^^^^^^^^^^^^^^^^^^
urllib3.exceptions.MaxRetryError: HTTPConnectionPool(host='localhost', port=45483): Max retries exceeded with url: /session/baafe3183db8687cb0a4edb742184ac9/frame (Caused by NewConnectionError('<urllib3.connection.HTTPConnection object at 0x73a981d4f350>: Failed to establish a new connection: [Errno 111] Connection refused'))
